Workbook

Sheet Cover
A1: Birmarket.az — Bitirmə Layihəsi: Test Sənədləri
A2: UI (Web) + API test ssenariləri, test case-lər, avtomatlaşdırma strategiyası
A4: Layihə | B4: Birmarket.az (Umico) — onlayn marketplace
A5: Test obyekti (URL) | B5: https://birmarket.az/ (Production, public)
A6: Hazırlayan | B6: Zərifə Babayeva
A7: Kurs / Qrup | B7: ABB Tech Academy — QA
A8: Versiya | B8: 1.1
A9: Tarix | B9: 13.10.2026
A10: Mühit | B10: Windows 11 / macOS, Google Chrome (son stabil versiya), 1920×1080; dil AZ; şəhər Bakı
A11: Test perspektivi | B11: Black Box (UI) + Grey Box (API)
A12: Tətbiq olunan texnikalar | B12: Equivalence Partitioning, Boundary Value Analysis, Decision Table, State Transition, Error Guessing
A14: Sheet-lər
A15: Test Scope | B15: Nə test olunur / nə test olunmur və səbəbləri
A16: Test Scenarios | B16: Yüksək səviyyəli ssenarilər — Guest və Login versiyaları ayrıca
A17: Test Cases | B17: UI test case-lər (strukturlu, manual/avtomat əsaslandırması ilə)
A18: Automation Strategy | B18: Manual vs avtomat seçim kriteriyaları və anti-flaky qaydalar
A19: RTM | B19: Ssenari → test case → avtomatlaşdırma izlənməsi (formula ilə)
A20: Summary | B20: Ümumi göstəricilər (formula ilə avtomatik hesablanır)
A21: Grooming Questions | B21: Tələblərdə qeyri-müəyyən məqamlar üzrə suallar və qəbul edilmiş fərziyyələr
A22: Assumptions & Risks | B22: Fərziyyələr, risklər və onların idarə olunması
A23: Bug Reports | B23: İcra zamanı tapılan defektlər
A24: API_* sheet-lər | B24: API (api.anarabbas.com, Final Project backlog): Test Plan, Scenarios, 168 Test Case, Decision Table, Coverage, Traceability, Grooming Questions
A26: Doldurma qaydası (Legend)
A27: Status | B27: Not Run / Pass / Fail / Blocked — icradan sonra Test Cases sheet-ində seçilir (dropdown)
A28: Automation | B28: Automated — avtomatlaşdırılıb / Manual — manual icra olunur
A29: Regression | B29: Yes — avtomat regression / Yes (Manual) — manual regression / No — regression-a daxil deyil
A30: Priority | B30: P1 - Critical / P2 - High / P3 - Medium / P4 - Low
A31: Actual Result / Execution Date / İcra növü | B31: Test Cases sheet-inin sonundakı sütunlar: faktiki nəticə, icra tarixi və icra üsulu (Avtomat / Manual)

Sheet Test Scope
A1: Test Scope
A2: Test obyekti: https://birmarket.az/ (Production). Real sifariş və ödəniş YARADILMIR.
A4: IN SCOPE
A5: Modul / Funksionallıq | B5: Səviyyə | C5: Səbəb | D5: Ssenari
A6: Ana səhifə və header | B6: UI | C6: Hər istifadəçinin giriş nöqtəsi; smoke üçün əsas | D6: TS_UI_01
A7: Dil seçimi (AZ/RU) | B7: UI | C7: İki dilli auditoriya, URL strukturuna təsir edir | D7: TS_UI_02
A8: Şəhər seçimi | B8: UI | C8: Çatdırılma şərtlərini müəyyən edir | D8: TS_UI_03
A9: Axtarış | B9: UI | C9: Satışın əsas giriş kanalı | D9: TS_UI_04
A10: Kataloq və kateqoriyalar | B10: UI | C10: Naviqasiyanın əsas yolu | D10: TS_UI_05
A11: Məhsul siyahısı (sıralama, filtr, pagination) | B11: UI | C11: Məhsulun tapılmasına birbaşa təsir edir | D11: TS_UI_06
A12: Məhsul detal səhifəsi (PDP) | B12: UI | C12: Alış qərarının verildiyi səhifə | D12: TS_UI_07
A13: Səbət (Guest və Login) | B13: UI | C13: Pul hesablaması — ən yüksək biznes riski | D13: TS_UI_08, TS_UI_12
A14: Seçilmişlər | B14: UI | C14: Guest vs Login davranış fərqi | D14: TS_UI_09
A15: Giriş/Qeydiyyat (telefon + SMS OTP) | B15: UI | C15: Login axını bütün şəxsi funksiyaların açarıdır | D15: TS_UI_10, TS_UI_11
A16: Checkout-a keçid (sifariş TƏSDİQLƏNMƏDƏN) | B16: UI | C16: Satış hunisinin son mərhələsi | D16: TS_UI_13
... A22: Backend API-lər | B22: API | C22: Kurs tərəfindən təqdim olunan API-lər (API_* sheet-lər) | D22: API_TS_*
A24: OUT OF SCOPE
A25: Modul / Funksionallıq | B25: Səbəb
A26: Real sifarişin təsdiqlənməsi və onlayn ödəniş | B26: Production mühitidir — real sifariş/ödəniş satıcıya və şirkətə zərər verir, real pul tələb edir
A27: Kredit və taksit müraciəti (Birbank) | B27: Real şəxsi və maliyyə məlumatları tələb edir, kredit tarixçəsinə təsir edir
A28: Bir Bonus xərcləmə və promokodun sifarişə tətbiqi | B28: Real bonus balansı, aktiv promokod və real sifariş tələb edir (bonus/promokod səhifələrinə baxış in scope-dadır)
A29: Məhsul rəyi yazmaq | B29: Production-da real kontent yaradır (data pollution), yalnız alınmış məhsula icazə verilir
A30: Satıcı portalı (business.umico.az) | B30: Ayrı sistemdir, korporativ hesab tələb edir
A31: Mobil tətbiqlər (iOS / Android) | B31: Layihə tələbi: yalnız web
A32: Performance / Load testing | B32: Production-a yük vermək qadağandır və etik deyil
A33: Security / Penetration testing | B33: İcazə tələb edir; yalnız əsas XSS sanity yoxlaması daxildir
A34: Üçüncü tərəf səhifələrinin məzmunu (sosial şəbəkələr, bir.az) | B34: Birmarket-in məsuliyyət sahəsi deyil
A36: ENTRY / EXIT KRİTERİYALARI
A37: Entry | B37: Sayt əlçatandır (HTTP 200), test hesabı və telefon hazırdır, test case-lər review olunub
A38: Exit | B38: Bütün P1 test case-lər icra olunub; P1/P2 açıq bug yoxdur; avtomatlaşdırılmış regression ardıcıl 3 run-da 100% stabil keçir

Sheet Test Scenarios
A1: Scenario ID | B1: Ssenari | C1: İstifadəçi növü | D1: Təsvir (nəyi test edirik?) | E1: Priority | F1: TC sayı
A2: TS_UI_01 | B2: Ana səhifə və header | C2: Guest | D2: Header elementləri, üst linklər, logo, sol kateqoriya paneli, banner karuseli, üstünlüklər zolağı, chat | E2: P1 - Critical | F2: =COUNTIF('Test Cases'!$J$2:$J$500,A2) -> 16
A3: TS_UI_02 | B3: Ana səhifə və header | C3: Login | D3: Login vəziyyətinin header-də əks olunması, profil menyusu | E3: P1 - Critical | F3: =COUNTIF('Test Cases'!$J$2:$J$500,A3) -> 2
A4: TS_UI_03 | B4: Dil seçimi (AZ / RU) | C4: Guest | D4: Dil dəyişmə, URL strukturu, naviqasiyada saxlanma, RU axtarış | E4: P2 - High | F4: =COUNTIF('Test Cases'!$J$2:$J$500,A4) -> 4
A5: TS_UI_04 | B5: Dil seçimi (AZ / RU) | C5: Login | D5: Dil dəyişdikdə sessiyanın saxlanması, kabinetin tərcüməsi | E5: P2 - High | F5: =COUNTIF('Test Cases'!$J$2:$J$500,A5) -> 2
A6: TS_UI_05 | B6: Şəhər seçimi | C6: Guest | D6: Şəhər seçimi, saxlanması və çatdırılma məlumatına təsiri | E6: P2 - High | F6: =COUNTIF('Test Cases'!$J$2:$J$500,A6) -> 4
A7: TS_UI_06 | B7: Şəhər seçimi | C7: Login | D7: Şəhərin hesabda saxlanması və checkout-a ötürülməsi | E7: P2 - High | F7: =COUNTIF('Test Cases'!$J$2:$J$500,A7) -> 3
A8: TS_UI_07 | B8: Məhsul axtarışı | C8: Guest | D8: Açar söz, tam ad, Enter, case-insensitive, nəticəsiz/boş/uzun/xüsusi sorğu, autocomplete | E8: P1 - Critical | F8: =COUNTIF('Test Cases'!$J$2:$J$500,A8) -> 12
A9: TS_UI_08 | B9: Məhsul axtarışı | C9: Login | D9: Login istifadəçi üçün nəticələrin guest ilə uyğunluğu | E9: P3 - Medium | F9: =COUNTIF('Test Cases'!$J$2:$J$500,A9) -> 1
A10: TS_UI_09 | B10: Kataloq və kateqoriya naviqasiyası | C10: Guest | D10: Kateqoriya menyusu, kateqoriya/alt kateqoriya səhifəsi, breadcrumb, 404 | E10: P1 - Critical | F10: =COUNTIF('Test Cases'!$J$2:$J$500,A10) -> 7
A11: TS_UI_10 | B11: Məhsul siyahısı: sıralama, filtr, səhifələmə | C11: Guest | D11: 6 sıralama seçimi, qiymət/brend/endirimli/xüsusiyyət filtrləri (EP/BVA/Decision Table), sıfırlama, pagination | E11: P1 - Critical | F11: =COUNTIF('Test Cases'!$J$2:$J$500,A11) -> 29
A12: TS_UI_11 | B12: Məhsul detal səhifəsi (PDP) | C12: Guest | D12: Kart↔PDP uyğunluğu, elementlər, variantlar, stok, satıcı, taksit, rəy, 404 | E12: P1 - Critical | F12: =COUNTIF('Test Cases'!$J$2:$J$500,A12) -> 14
A13: TS_UI_12 | B13: Məhsul detal səhifəsi (PDP) | C13: Login | D13: PDP-dən seçilmişlərə əlavə, rəy yazma hüququ | E13: P2 - High | F13: =COUNTIF('Test Cases'!$J$2:$J$500,A13) -> 2
... A30: TS_UI_29 | B30: Bir Bonus: ID kart və əməliyyat tarixçəsi | C30: Login | D30: Balans, bonus hesablaması, son əməliyyatlar, tarixçə filtrləri (tərəfdaş, dövr BVA, bonus növü) | E30: P2 - High | F30: =COUNTIF('Test Cases'!$J$2:$J$500,A30) -> 9

Sheet Test Cases
A1: Test Case ID | B1: Test Case Title | C1: Module / Feature | D1: Priority | E1: Test Type | F1: Preconditions | G1: Test Steps | H1: Test Data | I1: Expected Result | J1: Scenario ID | K1: Manual/Automation əsaslandırma | L1: Status | M1: Automation | N1: Regression | O1: Actual Result | P1: Execution Date | Q1: İcra növü
A2: TC_HOME_POS_001 | B2: Guest ana səhifəni açdıqda əsas header elementləri göstərilir | C2: Ana səhifə → Header | D2: P1 - Critical | E2: Pozitiv, Smoke | F2: 1. Brauzer: Google Chrome (son stabil versiya), incognito rejim (cookies/cache təmizdir) 2. İstifadəçi login olmayıb (Guest) 3. Dil: AZ, Şəhər: Bakı (default) | G2: 1. Brauzerdə ana səhifə URL-ni aç 2. Səhifənin tam yüklənməsini gözlə 3. Səhifə başlığını (title) yoxla 4. Header elementlərini müşahidə et | H2: URL: https://birmarket.az/ | I2: 1. Səhifə title-ı "BIRMARKET" sözünü ehtiva edir 2. Üst zolaqda görünür: "Çatdırılma və ödəmə", "Qaytarılma", "Zəmanət", "Birmarket-də satın", "915", dil seçicisi "AZ", "Qeydiyyat | Giriş" 3. Əsas header-də görünür: logo, "Şəhər: Bakı", "Məhsul kataloqu", "Məhsul axtar" placeholder-li axtarış sahəsi, "Axtar", "Seçilmişlər", "Səbət" 4. Xəta səhifəsi (404/500) göstərilmir | J2: TS_UI_01 | K2: Smoke testdir — hər deploy-dan sonra ilk yoxlanılan; locator-lar stabil, nəticə dinamik data-dan asılı deyil → avtomatlaşdırılır. | L2: Pass | M2: Automated | N2: Yes | O2: Gözlənilən nəticə ilə üst-üstə düşür. Gauge avtomat run (Chrome 154, guest): PASS. | P2: 06.10.2026 | Q2: Avtomat (Gauge + Selenium)
A3: TC_HOME_POS_002 | B3: Daxili səhifədən logoya klik istifadəçini ana səhifəyə qaytarır | C3: Ana səhifə → Logo naviqasiyası | D3: P3 - Medium | E3: Pozitiv | F3: 1. Brauzer: Google Chrome (son stabil versiya), incognito rejim (cookies/cache təmizdir) 2. İstifadəçi login olmayıb (Guest) 3. Dil: AZ, Şəhər: Bakı (default) 4. Kateqoriya səhifəsi açıqdır: https://birmarket.az/categories/2-telefonlar-ve-aksessuarlar | G3: 1. Header-dəki Birmarket logosuna klik et 2. Açılan səhifənin URL-ni yoxla | H3: Başlanğıc URL: https://birmarket.az/categories/2-telefonlar-ve-aksessuarlar | I3: 1. URL https://birmarket.az/ olur 2. Ana səhifənin banner bölməsi görünür | J3: TS_UI_01 | K3: Naviqasiyanın əsas elementi, deterministik nəticə (URL yoxlaması) → avtomatlaşdırılır. | L3: Pass | M3: Automated | N3: Yes | O3: Gözlənilən nəticə ilə üst-üstə düşür. Gauge avtomat run (Chrome 154, guest): PASS. | P3: 06.10.2026 | Q3: Avtomat (Gauge + Selenium)
A4: TC_HOME_POS_006 | B4: Header-in üst linkləri ("Çatdırılma və ödəmə", "Qaytarılma", "Zəmanət") müvafiq məlumat səhifələrini açır | C4: Ana səhifə → Üst məlumat linkləri | D4: P3 - Medium | E4: Pozitiv | F4: 1. Brauzer: Google Chrome (son stabil versiya), incognito rejim (cookies/cache təmizdir) 2. İstifadəçi login olmayıb (Guest) 3. Dil: AZ, Şəhər: Bakı (default) 4. Ana səhifə açıqdır: https://birmarket.az/ | G4: 1. "Çatdırılma və ödəmə" linkinə klik et, URL-i yoxla 2. Geri qayıt, "Qaytarılma" linkinə klik et, URL-i yoxla 3. Geri qayıt, "Zəmanət" linkinə klik et, URL-i yoxla | H4: Gözlənilən URL-lər: /shipping-payment, /questions-answers?target=cancel-refund, /questions-answers?target=warranty | I4: Hər link gözlənilən URL-i açır və səhifədə müvafiq başlıq/məzmun göstərilir | J4: TS_UI_01 | K4: Aşağı riskli, nadir dəyişən funksionallıq; regression ROI aşağıdır → manual. | L4: Not Run | M4: Manual | N4: No
A5: TC_HOME_POS_009 | B5: Ana səhifədə ikən logoya klik səhifəni yeniləyir və istifadəçini səhifənin yuxarısına qaytarır | C5: Ana səhifə → Logo (ana səhifədə) | D5: P4 - Low | E5: Pozitiv | F5: 1. Brauzer: Google Chrome (son stabil versiya), incognito rejim (cookies/cache təmizdir) 2. İstifadəçi login olmayıb (Guest) 3. Dil: AZ, Şəhər: Bakı (default) 4. Ana səhifə açıqdır: https://birmarket.az/ | G5: 1. Səhifəni aşağıya scroll et 2. Header-dəki Birmarket logosuna klik et 3. URL-i və səhifənin mövqeyini yoxla | H5: — | I5: 1. URL https://birmarket.az/ qalır 2. Səhifə yenidən yüklənir və ən yuxarı hissə (banner) göstərilir 3. Xəta yoxdur | J5: TS_UI_01 | K5: Vizual/scroll mövqeyi yoxlamasıdır, biznes riski aşağıdır → manual. | L5: Not Run | M5: Manual | N5: No
A6: TC_HOME_POS_010 | B6: "Bütün kateqoriyalar" sol paneldəki siyahını yerində genişləndirir | C6: Ana səhifə → Sol kateqoriya paneli | D6: P2 - High | E6: Pozitiv | F6: 1. Brauzer: Google Chrome (son stabil versiya), incognito rejim (cookies/cache təmizdir) 2. İstifadəçi login olmayıb (Guest) 3. Dil: AZ, Şəhər: Bakı (default) 4. Ana səhifə açıqdır: https://birmarket.az/ | G6: 1. Sol paneldəki görünən kateqoriyaları oxu 2. "Bütün kateqoriyalar"-a klik et 3. URL-i və paneli yoxla 4. Paneli aşağı scroll et | H6: — | I6: 1. URL dəyişmir (ayrı səhifəyə keçid olmur) 2. Panel yerində genişlənir, səhifənin qalan hissəsi tündləşir (overlay) 3. Panel scroll olunur və əvvəl görünməyən kateqoriyalar ("Məişət kimyası", "İdman və Əyləncə" və s.) göstərilir | J6: TS_UI_01 | K6: Davranış təsdiqlənib; login tələb etmir, deterministikdir → avtomatlaşdırılır. | Avtomatlaşdırma cəhdindən sonra Manual-a keçirildi: Kataloq paneli overlay/hover ilə açılır, stabil locator yoxdur. | L6: Pass | M6: Manual | N6: Yes (Manual) | O6: Siyahı yerində genişlənir, URL dəyişmir, overlay açılır (GQ_UI_25). PASS. | P6: 06.10.2026 | Q6: Manual (saytda yoxlanılıb)
A7: TC_HOME_POS_011 | B7: Sol paneldə kateqoriyaya klik müvafiq kateqoriya səhifəsini açır | C7: Ana səhifə → Sol kateqoriya paneli | D7: P2 - High | E7: Pozitiv | F7: 1. Brauzer: Google Chrome (son stabil versiya), incognito rejim (cookies/cache təmizdir) 2. İstifadəçi login olmayıb (Guest) 3. Dil: AZ, Şəhər: Bakı (default) 4. Ana səhifə açıqdır: https://birmarket.az/ | G7: 1. Sol paneldə "Məişət texnikası"-na klik et 2. URL-i və H1-i yoxla | H7: Kateqoriya: Məişət texnikası | I7: 1. URL "/categories/106-meishet-texnikasi" ehtiva edir 2. H1 = "Məişət texnikası" 3. Ən azı 1 məhsul kartı göstərilir | J7: TS_UI_01 | K7: Regression-a daxildir, hər release-də təkrarlanır; nəticə data-dan asılı olmayan invariantla yoxlanır (hardcode qiymət/ad yoxdur); xarici asılılıq yoxdur → avtomatlaşdırılır. | Avtomatlaşdırma cəhdindən sonra Manual-a keçirildi: Kataloq paneli overlay/hover ilə açılır, stabil locator yoxdur. | L7: Not Run | M7: Manual | N7: Yes (Manual)
A8: TC_HOME_POS_012 | B8: Sol paneldəki "Mega endirimlər" linki endirimlər səhifəsini açır | C8: Ana səhifə → Kampaniya linkləri | D8: P3 - Medium | E8: Pozitiv | F8: 1. Brauzer: Google Chrome (son stabil versiya), incognito rejim (cookies/cache təmizdir) 2. İstifadəçi login olmayıb (Guest) 3. Dil: AZ, Şəhər: Bakı (default) 4. Ana səhifə açıqdır: https://birmarket.az/ | G8: 1. Sol paneldə "Mega endirimlər"-ə klik et 2. URL-i və məhsulları yoxla | H8: — | I8: 1. URL "/mega-discounts" ehtiva edir 2. Göstərilən məhsul kartlarında endirim nişanı var | J8: TS_UI_01 | K8: Kampaniya məzmunu marketinq tərəfindən tez-tez dəyişir → manual. | L8: Not Run | M8: Manual | N8: No
A9: TC_HOME_POS_013 | B9: Üstünlüklər zolağında 4 məlumat bloku göstərilir və pulsuz çatdırılma həddi 50 ₼-dir | C9: Ana səhifə → Üstünlüklər zolağı | D9: P3 - Medium | E9: Pozitiv | F9: 1. Brauzer: Google Chrome (son stabil versiya), incognito rejim (cookies/cache təmizdir) 2. İstifadəçi login olmayıb (Guest) 3. Dil: AZ, Şəhər: Bakı (default) 4. Ana səhifə açıqdır: https://birmarket.az/ | G9: 1. Bannerin altındakı zolağı oxu | H9: — | I9: Bloklar: "500 000-dən çox məhsul", "50 ₼-dən başlayan sifarişlərə pulsuz çatdırılma", "Endirimlər və aksiyalar", "Birbank ilə 24 ayadək taksit" (checkout-dakı çatdırılma həddi ilə uyğun olmalıdır — TC_CHK_BVA_003/004) | J9: TS_UI_01 | K9: Marketinq mətni dəyişə bilər; dəyər checkout BVA testləri ilə çarpaz yoxlanılır → manual. | L9: Not Run | M9: Manual | N9: No
A10: TC_HOME_POS_014 | B10: "Birmarket-də satın" linki satıcı portalının (Business By Birmarket) ana səhifəsini açır | C10: Ana səhifə → Satıcı linki | D10: P3 - Medium | E10: Pozitiv | F10: 1. Brauzer: Google Chrome (son stabil versiya), incognito rejim (cookies/cache təmizdir) 2. İstifadəçi login olmayıb (Guest) 3. Dil: AZ, Şəhər: Bakı (default) 4. Ana səhifə açıqdır: https://birmarket.az/ | G10: 1. Üst zolaqda "Birmarket-də satın"-a klik et 2. Açılan səhifəni yoxla | H10: — | I10: 1. URL "https://business.umico.az" ilə başlayır 2. "Business By Birmarket" loqosu və "Onlayn mağazanızı yaradın və Bakıdan bütün Azərbaycana satış edin" başlığı göstərilir 3. "Satıcı olmaq", "Daxil ol", "Qeydiyyat" düymələri görünür | J10: TS_UI_01 | K10: Xarici/ayrı sistemə keçid (satıcı portalı scope-dan kənardır), yalnız keçid yoxlanılır → manual. | L10: Pass | M10: Manual | N10: No | O10: "Birmarket-də satın" → business.umico.az açılır (GQ_UI_26). PASS. | P10: 06.10.2026 | Q10: Manual (saytda yoxlanılıb)
A11: TC_HOME_POS_015 | B11: "915" seçicisi çağrı mərkəzinin iş saatlarını göstərir, nömrəyə klik zəng tətbiqini çağırır | C11: Ana səhifə → Qaynar xətt | D11: P4 - Low | E11: Pozitiv | F11: 1. Brauzer: Google Chrome (son stabil versiya), incognito rejim (cookies/cache təmizdir) 2. İstifadəçi login olmayıb (Guest) 3. Dil: AZ, Şəhər: Bakı (default) 4. Ana səhifə açıqdır: https://birmarket.az/ | G11: 1. Üst zolaqda "915" yanındakı oxa klik et 2. Açılan bloku oxu 3. "915" nömrəsinə klik et | H11: — | I11: 1. Blokda "Çağrı mərkəzinin iş saatları" — "Hər gün: 09:00 – 00:00" göstərilir 2. Nömrəyə klik brauzerin zəng tətbiqini açma dialoqunu çağırır (tel: link) | J11: TS_UI_01 | K11: Aşağı riskli, nadir dəyişən funksionallıq; regression ROI aşağıdır → manual. | L11: Pass | M11: Manual | N11: No | O11: "915" blokunda "Hər gün: 09:00 – 00:00" göstərilir, nömrə tel: linkdir (GQ_UI_26). PASS. | P11: 06.10.2026 | Q11: Manual (saytda yoxlanılıb)
A12: TC_HOME_POS_016 | B12: Canlı dəstək (chat) düyməsi söhbət pəncərəsini açır | C12: Ana səhifə → Chat widget | D12: P3 - Medium | E12: Pozitiv | F12: 1. Brauzer: Google Chrome (son stabil versiya), incognito rejim (cookies/cache təmizdir) 2. İstifadəçi login olmayıb (Guest) 3. Dil: AZ, Şəhər: Bakı (default) 4. Ana səhifə açıqdır: https://birmarket.az/ | G12: 1. Sağ aşağı küncdəki chat düyməsinə klik et 2. Açılan pəncərəni müşahidə et 3. Pəncərəni bağla | H12: — | I12: 1. Söhbət pəncərəsi açılır 2. Bağlandıqdan sonra düymə yenidən görünür (Mesaj GÖNDƏRİLMİR — real operator yükü yaratmamaq üçün) | J12: TS_UI_01 | K12: Üçüncü tərəf widget-i, iframe və async yükləmə → avtomatlaşdırma qeyri-stabil; real dəstək xidmətinə təsir riski → manual. | L12: Not Run | M12: Manual | N12: No
A13: TC_HOME_POS_017 | B13: "Günün endirimi" blokundakı kampaniya taymeri geri sayır | C13: Ana səhifə → Günün endirimi | D13: P3 - Medium | E13: Pozitiv | F13: 1. Brauzer: Google Chrome (son stabil versiya), incognito rejim (cookies/cache təmizdir) 2. İstifadəçi login olmayıb (Guest) 3. Dil: AZ, Şəhər: Bakı (default) 4. Ana səhifə açıqdır: https://birmarket.az/ | G13: 1. "Günün endirimi" bölməsinə scroll et 2. "Kampaniyanın bitmə müddəti" dəyərini oxu 3. 5 saniyə gözlə və dəyəri yenidən oxu | H13: — | I13: 1. Taymer SS:DD:SS formatındadır 2. 5 saniyə sonra dəyər ~5 saniyə azalır 3. Blokda endirimli məhsul kartları göstərilir | J13: TS_UI_01 | K13: Kampaniya hər gün aktiv olmaya bilər və vaxta bağlıdır → avtomatlaşdırma flaky olar → manual. | L13: Not Run | M13: Manual | N13: No
A14: TC_HOME_POS_018 | B14: Brauzer bildirişləri təklifində "Ləğv et" seçildikdə təklif bağlanır və dərhal təkrar göstərilmir | C14: Ana səhifə → Bildiriş icazəsi təklifi | D14: P3 - Medium | E14: Pozitiv, State Transition | F14: 1. Brauzer: Google Chrome (son stabil versiya), incognito rejim (cookies/cache təmizdir) 2. İstifadəçi login olmayıb (Guest) 3. Dil: AZ, Şəhər: Bakı (default) 4. "Brauzerinizdə bildirişlər almaq istəyirsinizmi?" təklifi göstərilir | G14: 1. Təklifdə "Ləğv et"-ə klik et 2. Səhifəni yenilə (F5) 3. Başqa səhifəyə keç | H14: — | I14: 1. Təklif bağlanır 2. Yeniləmədən və naviqasiyadan sonra təklif təkrar göstərilmir (təkrar göstərilmə müddəti — GQ_UI_35) | J14: TS_UI_01 | K14: Brauzer icazə vəziyyəti və cookie-dən asılıdır; native dialoqla əlaqə avtomatlaşdırmada idarə olunmur → manual. | L14: Not Run | M14: Manual | N14: No
A15: TC_HOME_POS_019 | B15: Bildiriş təklifində "İcazə ver" brauzerin öz icazə dialoqunu çağırır | C15: Ana səhifə → Bildiriş icazəsi təklifi | D15: P4 - Low | E15: Pozitiv | F15: 1. Brauzer: Google Chrome (son stabil versiya), incognito rejim (cookies/cache təmizdir) 2. İstifadəçi login olmayıb (Guest) 3. Dil: AZ, Şəhər: Bakı (default) 4. Bildiriş təklifi göstərilir | G15: 1. "İcazə ver"-ə klik et 2. Ekranı müşahidə et | H15: — | I15: Brauzerin native "Bildirişləri göstər — İcazə ver / Blokla" dialoqu açılır; saytın təklifi bağlanır | J15: TS_UI_01 | K15: Native brauzer dialoqu WebDriver ilə etibarlı idarə olunmur → manual. | L15: Not Run | M15: Manual | N15: No
A16: TC_HOME_UI_003 | B16: Ana səhifə banner karuseli dəyişir və banner klikləndikdə aksiya səhifəsi açılır | C16: Ana səhifə → Banner karusel | D16: P3 - Medium | E16: UI | F16: 1. Brauzer: Google Chrome (son stabil versiya), incognito rejim (cookies/cache təmizdir) 2. İstifadəçi login olmayıb (Guest) 3. Dil: AZ, Şəhər: Bakı (default) 4. Ana səhifə açıqdır: https://birmarket.az/ | G16: 1. Banner karuselini 10 saniyə müşahidə et 2. Karuselin sağ oxuna klik et 3. Aktiv bannerə klik et | H16: — | I16: 1. Bannerlər avtomatik növbə ilə dəyişir, aktiv banner nöqtə göstəricisində (7 nöqtə) qeyd olunur 2. Ox kliki ilə növbəti banner göstərilir 3. Banner kliki URL-i "/flash_sale/" olan aksiya səhifəsini açır, səhifədə məhsul kartları var | J16: TS_UI_01 | K16: Vizual/UX yoxlama insan qiyməti tələb edir, məzmun marketinq tərəfindən tez-tez dəyişir → avtomatlaşdırma flaky olar, ROI aşağıdır. | L16: Not Run | M16: Manual | N16: No
A17: TC_HOME_UI_007 | B17: Səhifə aşağı scroll edildikdə header (axtarış və səbət) görünən qalır | C17: Ana səhifə → Sticky header | D17: P4 - Low | E17: UI | F17: 1. Brauzer: Google Chrome (son stabil versiya), incognito rejim (cookies/cache təmizdir) 2. İstifadəçi login olmayıb (Guest) 3. Dil: AZ, Şəhər: Bakı (default) 4. Ana səhifə açıqdır: https://birmarket.az/ | G17: 1. Səhifəni ən aşağıya qədər scroll et 2. Ekranın yuxarı hissəsini müşahidə et | H17: — | I17: Axtarış sahəsi və səbət ikonu ekranın yuxarısında görünən qalır | J17: TS_UI_01 | K17: Vizual/UX yoxlama insan qiyməti tələb edir, məzmun marketinq tərəfindən tez-tez dəyişir → avtomatlaşdırma flaky olar, ROI aşağıdır. | L17: Not Run | M17: Manual | N17: No
A18: TC_HOME_POS_004 | B18: [Login] Login olmuş istifadəçinin header-ində "Şəxsi hesabım" göstərilir, "Qeydiyyat | Giriş" göstərilmir | C18: Ana səhifə (Login) → Header | D18: P1 - Critical | E18: Pozitiv | F18: 1. Brauzer: Google Chrome (son stabil versiya) 2. Test hesabı Birmarket-də qeydiyyatdadır, telefon nömrəsi SMS qəbul edir (test icraçısının əlindədir) 3. İstifadəçi həmin hesabla login olub (header-də "Şəxsi hesabım" görünür) 4. Ana səhifə açıqdır: https://birmarket.az/ | G18: 1. Header-i müşahidə et 2. Səhifəni yenilə (F5) 3. Header-i yenidən müşahidə et | H18: — | I18: 1. Üst zolaqda "Şəxsi hesabım" göstərilir 2. "Qeydiyyat | Giriş" linki göstərilmir 3. Yeniləmədən sonra login vəziyyəti saxlanılır | J18: TS_UI_02 | K18: SMS OTP real telefon tələb edir, prod-da OTP bypass yoxdur, SMS limitləri var → stabil avtomatlaşdırmaq mümkün deyil. Biznes kritik olduğu üçün manual regression-a daxildir. | L18: Pass | M18: Manual | N18: Yes (Manual) | O18: Login vəziyyətində header-də "Şəxsi hesabım" göstərilir, "Qeydiyyat | Giriş" yoxdur; F5-dən sonra login vəziyyəti saxlanılır. PASS. | P18: 07.10.2026 | Q18: Manual (saytda yoxlanılıb)
A19: TC_HOME_POS_005 | B19: [Login] "Şəxsi hesabım"-a klik edildikdə bütün kabinet bölmələri olan menyu açılır | C19: Ana səhifə (Login) → Profil menyusu | D19: P2 - High | E19: Pozitiv | F19: 1. Brauzer: Google Chrome (son stabil versiya) 2. Test hesabı Birmarket-də qeydiyyatdadır, telefon nömrəsi SMS qəbul edir (test icraçısının əlindədir) 3. İstifadəçi həmin hesabla login olub (header-də "Şəxsi hesabım" görünür) 4. Ana səhifə açıqdır: https://birmarket.az/ | G19: 1. Header-dəki "Şəxsi hesabım"-a klik et 2. Açılan menyunun bəndlərini oxu | H19: Gözlənilən bəndlər: Hesab, Bildirişlər, Mənim sifarişlərim, Mesaj, Promokodlar, Kredit müraciətləri, Seçilmişlər, Mənim rəylərim, Mənim ünvanlarım, Mənim ID kartım, Əməliyyat tarixçəsi, Çıxış | I19: 1. Menyu açılır, "birmarket" və "bir bonus" bölmələri ayrıca göstərilir 2. Menyuda dəqiq bu bəndlər var: Hesab, Bildirişlər, Mənim sifarişlərim, Mesaj, Promokodlar, Kredit müraciətləri, Seçilmişlər, Mənim rəylərim, Mənim ünvanlarım, Mənim ID kartım, Əməliyyat tarixçəsi, Çıxış 3. Oxunmamış bildiriş varsa "Bildirişlər" yanında say nişanı göstərilir | J19: TS_UI_02 | K19: SMS OTP real telefon tələb edir, prod-da OTP bypass yoxdur, SMS limitləri var → stabil avtomatlaşdırmaq mümkün deyil. Biznes kritik olduğu üçün manual regression-a daxildir. | L19: Not Run | M19: Manual | N19: Yes (Manual)
A20: TC_LANG_POS_001 | B20: Dil AZ-dan RU-ya dəyişdirildikdə URL /ru prefiksi alır və interfeys rus dilində göstərilir | C20: Dil seçimi → AZ→RU | D20: P2 - High | E20: Pozitiv | F20: 1. Brauzer: Google Chrome (son stabil versiya), incognito rejim (cookies/cache təmizdir) 2. İstifadəçi login olmayıb (Guest) 3. Dil: AZ, Şəhər: Bakı (default) 4. Ana səhifə açıqdır: https://birmarket.az/ | G20: 1. Header-dəki dil seçicisinə (AZ) klik et 2. "Русский" seçimini et 3. URL-i yoxla 4. Header mətnlərini yoxla | H20: Dil: Русский | I20: 1. URL "https://birmarket.az/ru" ilə başlayır 2. Dil seçicisi "RU" göstərir 3. Header mətnləri rus dilindədir (məs. "Qeydiyyat | Giriş" əvəzinə rusca qarşılığı) | J20: TS_UI_03 | K20: Regression-a daxildir, hər release-də təkrarlanır; nəticə data-dan asılı olmayan invariantla yoxlanır (hardcode qiymət/ad yoxdur); xarici asılılıq yoxdur → avtomatlaşdırılır. | L20: Pass | M20: Automated | N20: Yes | O20: Gözlənilən nəticə ilə üst-üstə düşür. Gauge avtomat run (Chrome 154, guest): PASS. | P20: 06.10.2026 | Q20: Avtomat (Gauge + Selenium)
A21: TC_LANG_POS_002 | B21: Dil RU-dan AZ-a qaytarıldıqda URL-dən /ru prefiksi silinir və interfeys AZ dilində göstərilir | C21: Dil seçimi → RU→AZ | D21: P2 - High | E21: Pozitiv | F21: 1. Brauzer: Google Chrome (son stabil versiya), incognito rejim (cookies/cache təmizdir) 2. İstifadəçi login olmayıb (Guest) 3. Dil: AZ, Şəhər: Bakı (default) 4. Ana səhifə RU dilində açıqdır: https://birmarket.az/ru | G21: 1. Dil seçicisinə (RU) klik et 2. "Azərbaycan" seçimini et 3. URL-i yoxla 4. Header mətnlərini yoxla | H21: Dil: Azərbaycan | I21: 1. URL-də "/ru" prefiksi yoxdur 2. Dil seçicisi "AZ" göstərir 3. Header-də "Qeydiyyat | Giriş" mətni görünür | J21: TS_UI_03 | K21: Regression-a daxildir, hər release-də təkrarlanır; nəticə data-dan asılı olmayan invariantla yoxlanır (hardcode qiymət/ad yoxdur); xarici asılılıq yoxdur → avtomatlaşdırılır. | L21: Pass | M21: Automated | N21: Yes | O21: Gözlənilən nəticə ilə üst-üstə düşür. Gauge avtomat run (Chrome 154, guest): PASS. | P21: 06.10.2026 | Q21: Avtomat (Gauge + Selenium)
A22: TC_LANG_POS_003 | B22: RU dili seçildikdən sonra kateqoriyaya keçid zamanı dil saxlanılır | C22: Dil seçimi → Naviqasiyada saxlanma | D22: P2 - High | E22: Pozitiv | F22: 1. Brauzer: Google Chrome (son stabil versiya), incognito rejim (cookies/cache təmizdir) 2. İstifadəçi login olmayıb (Guest) 3. Dil: AZ, Şəhər: Bakı (default) 4. Ana səhifə RU dilində açıqdır: https://birmarket.az/ru | G22: 1. Kataloq menyusunu aç 2. 1-ci kateqoriyaya klik et 3. URL-i və H1 başlığını yoxla | H22: — | I22: 1. URL "https://birmarket.az/ru/categories/" ilə başlayır 2. H1 başlığı rus dilindədir (kiril əlifbası) | J22: TS_UI_03 | K22: Regression-a daxildir, hər release-də təkrarlanır; nəticə data-dan asılı olmayan invariantla yoxlanır (hardcode qiymət/ad yoxdur); xarici asılılıq yoxdur → avtomatlaşdırılır. | Avtomatlaşdırma cəhdindən sonra Manual-a keçirildi: Kateqoriya keçidi overlay menyudan asılıdır. | L22: Not Run | M22: Manual | N22: Yes (Manual)
A23: TC_LANG_POS_004 | B23: RU interfeysində kiril əlifbası ilə axtarış nəticə qaytarır | C23: Dil seçimi → RU axtarış | D23: P2 - High | E23: Pozitiv | F23: 1. Brauzer: Google Chrome (son stabil versiya), incognito rejim (cookies/cache təmizdir) 2. İstifadəçi login olmayıb (Guest) 3. Dil: AZ, Şəhər: Bakı (default) 4. Ana səhifə RU dilində açıqdır: https://birmarket.az/ru | G23: 1. Axtarış sahəsinə açar sözü daxil et 2. Axtarışı icra et 3. Nəticələri yoxla | H23: Açar söz: телефон | I23: 1. Ən azı 1 məhsul kartı göstərilir 2. URL "/ru" prefiksini saxlayır | J23: TS_UI_03 | K23: Regression-a daxildir, hər release-də təkrarlanır; nəticə data-dan asılı olmayan invariantla yoxlanır (hardcode qiymət/ad yoxdur); xarici asılılıq yoxdur → avtomatlaşdırılır. | L23: Pass | M23: Automated | N23: Yes | O23: RU interfeysində "телефон" axtarışı nəticə qaytardı. PASS. | P23: 06.10.2026 | Q23: Avtomat (Gauge + Selenium)
A24: TC_LANG_POS_005 | B24: [Login] Login istifadəçi dili RU-ya dəyişdikdə sessiya saxlanılır | C24: Dil seçimi (Login) → Sessiya | D24: P2 - High | E24: Pozitiv, State Transition | F24: 1. Brauzer: Google Chrome (son stabil versiya) 2. Test hesabı Birmarket-də qeydiyyatdadır, telefon nömrəsi SMS qəbul edir (test icraçısının əlindədir) 3. İstifadəçi həmin hesabla login olub (header-də "Şəxsi hesabım" görünür) 4. Ana səhifə açıqdır: https://birmarket.az/ | G24: 1. Dil seçicisindən "Русский" seç 2. Header-i yoxla 3. Səbət ikonundakı sayğacı yoxla | H24: Dil: Русский | I24: 1. İstifadəçi login qalır ("Şəxsi hesabım" görünür) 2. Səbət sayğacı dil dəyişməzdən əvvəlki ilə eynidir | J24: TS_UI_04 | K24: SMS OTP real telefon tələb edir, prod-da OTP bypass yoxdur, SMS limitləri var → stabil avtomatlaşdırmaq mümkün deyil. Biznes kritik olduğu üçün manual regression-a daxildir. | L24: Not Run | M24: Manual | N24: Yes (Manual)
A25: TC_LANG_POS_006 | B25: [Login] Şəxsi kabinet səhifələri RU dilində tam tərcümə olunmuş göstərilir | C25: Dil seçimi (Login) → Kabinet tərcüməsi | D25: P3 - Medium | E25: UI | F25: 1. Brauzer: Google Chrome (son stabil versiya) 2. Test hesabı Birmarket-də qeydiyyatdadır, telefon nömrəsi SMS qəbul edir (test icraçısının əlindədir) 3. İstifadəçi həmin hesabla login olub (header-də "Şəxsi hesabım" görünür) 4. Dil: Русский | G25: 1. "Şəxsi hesabım" menyusunu aç 2. Şəxsi kabinetə keç 3. "Mənim sifarişlərim" bölməsinə keç 4. Hər səhifədə mətnləri yoxla | H25: — | I25: Kabinet səhifələrində AZ dilində qalmış (tərcümə olunmamış) mətn yoxdur | J25: TS_UI_04 | K25: OTP ilə login tələb edir (prod-da bypass yoxdur) → avtomatlaşdırıla bilmir. Biznes riski orta/aşağı olduğu üçün regression-a daxil edilmir. | L25: Not Run | M25: Manual | N25: No
A26: TC_CITY_NEG_007 | B26: Şəhər pəncərəsi seçim etmədən "X" ilə bağlandıqda şəhər dəyişmir | C26: Şəhər seçimi → Pəncərənin bağlanması | D26: P3 - Medium | E26: Neqativ, State Transition | F26: 1. Brauzer: Google Chrome (son stabil versiya), incognito rejim (cookies/cache təmizdir) 2. İstifadəçi login olmayıb (Guest) 3. Dil: AZ, Şəhər: Bakı (default) 4. Ana səhifə açıqdır: https://birmarket.az/ | G26: 1. Header-dəki "Şəhər: Bakı"-ya klik et 2. Pəncərədə heç bir şəhər seçmə 3. Sağ yuxarıdakı "X"-ə klik et 4. Header-i yoxla | H26: — | I26: 1. Pəncərə bağlanır 2. Header-də "Şəhər: Bakı" qalır | J26: TS_UI_05 | K26: Regression-a daxildir, hər release-də təkrarlanır; nəticə data-dan asılı olmayan invariantla yoxlanır (hardcode qiymət/ad yoxdur); xarici asılılıq yoxdur → avtomatlaşdırılır. | L26: Pass | M26: Automated | N26: Yes | O26: Pəncərə X ilə bağlandı, header-də "Şəhər: Bakı" dəyişmədi. PASS. | P26: 06.10.2026 | Q26: Avtomat (Gauge + Selenium)
A27: TC_CITY_POS_001 | B27: Şəhər siyahısından "Gəncə" seçildikdə header-də seçilmiş şəhər göstərilir | C27: Şəhər seçimi → Şəhər dəyişmə | D27: P2 - High | E27: Pozitiv | F27: 1. Brauzer: Google Chrome (son stabil versiya), incognito rejim (cookies/cache təmizdir) 2. İstifadəçi login olmayıb (Guest) 3. Dil: AZ, Şəhər: Bakı (default) 4. Ana səhifə açıqdır: https://birmarket.az/ | G27: 1. Header-dəki "Şəhər: Bakı" elementinə klik et 2. Açılan "Şəhərinizi seçin" siyahısından şəhəri seç 3. Header-dəki şəhər mətnini yoxla | H27: Şəhər: Gəncə | I27: 1. Şəhər siyahısı bağlanır 2. Header-də "Şəhər: Gəncə" göstərilir | J27: TS_UI_05 | K27: Şəhər seçimi çatdırılma şərtlərinə təsir edir; deterministik nəticə, stabil locator → avtomatlaşdırılır. | L27: Pass | M27: Automated | N27: Yes | O27: Gözlənilən nəticə ilə üst-üstə düşür. Gauge avtomat run (Chrome 154, guest): PASS. | P27: 06.10.2026 | Q27: Avtomat (Gauge + Selenium)
A28: TC_CITY_POS_002 | B28: Seçilmiş şəhər səhifə yeniləndikdən sonra saxlanılır | C28: Şəhər seçimi → Persistence | D28: P2 - High | E28: Pozitiv | F28: 1. Brauzer: Google Chrome (son stabil versiya), incognito rejim (cookies/cache təmizdir) 2. İstifadəçi login olmayıb (Guest) 3. Dil: AZ, Şəhər: Bakı (default) 4. Ana səhifə açıqdır: https://birmarket.az/ | G28: 1. Header-dəki şəhər elementinə klik et 2. Şəhəri seç 3. Səhifəni yenilə (F5) 4. Header-dəki şəhər mətnini yoxla | H28: Şəhər: Sumqayıt | I28: Səhifə yeniləndikdən sonra header-də "Şəhər: Sumqayıt" göstərilir (default "Bakı"-ya qayıtmır) | J28: TS_UI_05 | K28: State persistence bug-ları regression-da tez-tez qayıdır; deterministikdir → avtomatlaşdırılır. | L28: Pass | M28: Automated | N28: Yes | O28: Gözlənilən nəticə ilə üst-üstə düşür. Gauge avtomat run (Chrome 154, guest): PASS. | P28: 06.10.2026 | Q28: Avtomat (Gauge + Selenium)
A29: TC_CITY_POS_003 | B29: Şəhər dəyişdirildikdə PDP-dəki çatdırılma məlumatı yenilənir | C29: Şəhər seçimi → Çatdırılma məlumatı | D29: P2 - High | E29: Pozitiv | F29: 1. Brauzer: Google Chrome (son stabil versiya), incognito rejim (cookies/cache təmizdir) 2. İstifadəçi login olmayıb (Guest) 3. Dil: AZ, Şəhər: Bakı (default) 4. Kateqoriya səhifəsi açıqdır: https://birmarket.az/categories/2-telefonlar-ve-aksessuarlar 5. Məhsul seçim qaydası: kateqoriyada stokda olan ilk məhsul kartı (qiymət/ad hardcode edilmir) — PDP açıqdır | G29: 1. PDP-dəki çatdırılma tarixini/məlumatını qeyd et 2. Header-dən şəhəri dəyiş 3. PDP-dəki çatdırılma məlumatını yenidən oxu | H29: Şəhər: Bakı → Naxçıvan | I29: Çatdırılma məlumatı seçilmiş şəhərə uyğun yenilənir (Bakı üçün göstərilən məlumatla eyni qalmır və ya çatdırılma mümkün olmadığı bildirilir) | J29: TS_UI_05 | K29: Nəticə prod-da dinamik dəyişən data-dan (stok, sifariş tarixçəsi, məhsul sayı) asılıdır → avtomatlaşdırma flaky olar → manual. | L29: Not Run | M29: Manual | N29: No
A30: TC_CITY_POS_004 | B30: [Login] Login istifadəçinin seçdiyi şəhər logout və təkrar login-dən sonra saxlanılır | C30: Şəhər seçimi (Login) → Hesabda saxlanma | D30: P3 - Medium | E30: Pozitiv, State Transition | F30: 1. Brauzer: Google Chrome (son stabil versiya) 2. Test hesabı Birmarket-də qeydiyyatdadır, telefon nömrəsi SMS qəbul edir (test icraçısının əlindədir) 3. İstifadəçi həmin hesabla login olub (header-də "Şəxsi hesabım" görünür) 4. Ana səhifə açıqdır: https://birmarket.az/ | G30: 1. Şəhəri dəyiş 2. Logout et 3. Təkrar OTP ilə login ol 4. Header-dəki şəhəri yoxla | H30: Şəhər: Gəncə | I30: Header-də "Şəhər: Gəncə" göstərilir (GQ_UI_13) | J30: TS_UI_06 | K30: OTP ilə login tələb edir (prod-da bypass yoxdur) → avtomatlaşdırıla bilmir. Biznes riski orta/aşağı olduğu üçün regression-a daxil edilmir. | L30: Not Run | M30: Manual | N30: No
A31: TC_CITY_POS_005 | B31: [Login] Checkout-da çatdırılma şəhəri header-də seçilmiş şəhərlə uyğun gəlir | C31: Şəhər seçimi (Login) → Checkout | D31: P2 - High | E31: Pozitiv | F31: 1. Brauzer: Google Chrome (son stabil versiya) 2. Test hesabı Birmarket-də qeydiyyatdadır, telefon nömrəsi SMS qəbul edir (test icraçısının əlindədir) 3. İstifadəçi həmin hesabla login olub (header-də "Şəxsi hesabım" görünür) 4. Header-də şəhər: Sumqayıt 5. Səbətdə 1 məhsul var | G31: 1. Səbətə keç 2. "Sifarişi rəsmiləşdir"-ə klik et 3. Çatdırılma bölməsində şəhəri yoxla 4. Sifarişi TƏSDİQLƏMƏ | H31: Şəhər: Sumqayıt | I31: Checkout-da çatdırılma şəhəri "Sumqayıt" kimi göstərilir və ya ilkin seçilmiş olur | J31: TS_UI_06 | K31: OTP ilə login tələb edir (prod-da bypass yoxdur) → avtomatlaşdırıla bilmir. Biznes riski orta/aşağı olduğu üçün regression-a daxil edilmir. | L31: Not Run | M31: Manual | N31: No
A32: TC_CITY_POS_006 | B32: [Login→Logout] Logout-dan sonra "Şəhərinizi seçin" pəncərəsi avtomatik açılır | C32: Şəhər seçimi (Login→Logout) → Avtomatik pəncərə | D32: P3 - Medium | E32: Pozitiv, State Transition | F32: 1. Brauzer: Google Chrome (son stabil versiya) 2. Test hesabı Birmarket-də qeydiyyatdadır, telefon nömrəsi SMS qəbul edir (test icraçısının əlindədir) 3. İstifadəçi həmin hesabla login olub (header-də profil ikonu görünür) 4. Header-də şəhər: Bakı | G32: 1. "Şəxsi hesabım" → "Çıxış"-a klik et 2. Açılan ekranı müşahidə et 3. Pəncərədə seçilmiş şəhəri yoxla | H32: — | I32: 1. "Şəhərinizi seçin" pəncərəsi avtomatik açılır 2. "Bakı" ✓ işarəsi ilə seçili göstərilir 3. Siyahıda bütün şəhərlər əlifba sırası ilə sütunlarda göstərilir (GQ_UI_13) | J32: TS_UI_06 | K32: OTP ilə login tələb edir (prod-da bypass yoxdur) → avtomatlaşdırıla bilmir. Biznes riski orta/aşağı olduğu üçün regression-a daxil edilmir. | L32: Not Run | M32: Manual | N32: No
A33: TC_SRCH_EDGE_005 | B33: Axtarışa HTML/JS kodu daxil edildikdə kod icra olunmur və mətn kimi işlənir | C33: Axtarış → Xüsusi simvollar | D33: P2 - High | E33: Neqativ, Edge | F33: 1. Brauzer: Google Chrome (son stabil versiya), incognito rejim (cookies/cache təmizdir) 2. İstifadəçi login olmayıb (Guest) 3. Dil: AZ, Şəhər: Bakı (default) 4. Ana səhifə açıqdır: https://birmarket.az/ | G33: 1. Axtarış sahəsinə test datanı daxil et 2. "Axtar" düyməsinə klik et 3. Səhifəni müşahidə et | H33: Açar söz: <script>alert(1)</script> | I33: 1. Brauzerdə alert pəncərəsi açılmır 2. Səhifədə düz mətn kimi göstərilir: Sorğuya uyğun məhsul tapılmadı "<script>alert(1)</script>" 3. Səhifə 500 xətası vermir | J33: TS_UI_07 | K33: Bir dəfəlik təhlükəsizlik sanity yoxlamasıdır; tam security testi scope-dan kənardır, funksional regression-a aid deyil → manual. | L33: Not Run | M33: Manual | N33: No
A34: TC_SRCH_EDGE_007 | B34: Çox uzun (256 simvol) sorğu ilə axtarış sistemi çökdürmür | C34: Axtarış → Uzun sorğu | D34: P3 - Medium | E34: Edge | F34: 1. Brauzer: Google Chrome (son stabil versiya), incognito rejim (cookies/cache təmizdir) 2. İstifadəçi login olmayıb (Guest) 3. Dil: AZ, Şəhər: Bakı (default) 4. Ana səhifə açıqdır: https://birmarket.az/ | G34: 1. Axtarış sahəsinə test datanı daxil et 2. "Axtar" düyməsinə klik et 3. Səhifəni müşahidə et | H34: Açar söz: "a" simvolu × 256 | I34: 1. Səhifə 500/timeout xətası vermir 2. Sorğuya uyğun məhsul tapılmadı "aaa…" mesajı göstərilir və ya sahə simvol limitindən artığını qəbul etmir | J34: TS_UI_07 | K34: Edge case, bir dəfəlik exploratory yoxlama; regression dəyəri aşağı → manual. | L34: Not Run | M34: Manual | N34: No
A35: TC_SRCH_EDGE_012 | B35: Tək simvolla ("a") axtarış sistemi çökdürmür | C35: Axtarış → Minimum uzunluq | D35: P3 - Medium | E35: Edge, BVA | F35: 1. Brauzer: Google Chrome (son stabil versiya), incognito rejim (cookies/cache təmizdir) 2. İstifadəçi login olmayıb (Guest) 3. Dil: AZ, Şəhər: Bakı (default) 4. Ana səhifə açıqdır: https://birmarket.az/ | G35: 1. Axtarış sahəsinə 1 simvol daxil et 2. Axtarışı icra et 3. Nəticəni müşahidə et | H35: Açar söz: a (1 simvol) | I35: Ya nəticələr göstərilir, ya da minimum simvol sayı barədə mesaj göstərilir; 500 xətası yoxdur (GQ_UI_20) | J35: TS_UI_07 | K35: Gözlənilən davranış tələbdə müəyyən deyil (Grooming Questions sheet-ə bax). Cavab gəlməyənə qədər manual; təsdiqdən sonra avtomatlaşdırma namizədidir. | L35: Not Run | M35: Manual | N35: No
A36: TC_SRCH_NEG_003 | B36: Mövcud olmayan açar sözlə axtarışda məhsul qaytarılmır və boş nəticə mesajı göstərilir | C36: Axtarış → Nəticəsiz sorğu | D36: P1 - Critical | E36: Neqativ | F36: 1. Brauzer: Google Chrome (son stabil versiya), incognito rejim (cookies/cache təmizdir) 2. İstifadəçi login olmayıb (Guest) 3. Dil: AZ, Şəhər: Bakı (default) 4. Ana səhifə açıqdır: https://birmarket.az/ | G36: 1. Axtarış sahəsinə açar sözü daxil et 2. "Axtar" düyməsinə klik et 3. Nəticə səhifəsini müşahidə et | H36: Açar söz: qwxzqwxz123 | I36: 1. Məhsul kartı sayı = 0 2. Mesaj göstərilir: Sorğuya uyğun məhsul tapılmadı "qwxzqwxz123" 3. Alt mətn göstərilir: "Yazılış qaydasını yoxlayın, digər açar sözlərini istifadə edin və ya axtarışı kateqoriya seçimindən başlayın" 4. Səhifə xəta vermir (500 yoxdur) | J36: TS_UI_07 | K36: Regression-a daxildir, hər release-də təkrarlanır; nəticə data-dan asılı olmayan invariantla yoxlanır (hardcode qiymət/ad yoxdur); xarici asılılıq yoxdur → avtomatlaşdırılır. | L36: Pass | M36: Automated | N36: Yes | O36: Gözlənilən nəticə ilə üst-üstə düşür. Gauge avtomat run (Chrome 154, guest): PASS. | P36: 06.10.2026 | Q36: Avtomat (Gauge + Selenium)
A37: TC_SRCH_NEG_004 | B37: Boş axtarış sahəsi ilə "Axtar" düyməsinə klik edildikdə axtarış icra olunmur | C37: Axtarış → Boş sorğu | D37: P2 - High | E37: Neqativ, Edge | F37: 1. Brauzer: Google Chrome (son stabil versiya), incognito rejim (cookies/cache təmizdir) 2. İstifadəçi login olmayıb (Guest) 3. Dil: AZ, Şəhər: Bakı (default) 4. Ana səhifə açıqdır: https://birmarket.az/ | G37: 1. Axtarış sahəsini boş saxla 2. "Axtar" düyməsinə klik et 3. URL-i və səhifəni müşahidə et | H37: Açar söz: (boş) | I37: 1. Heç bir reaksiya olmur: nəticə səhifəsinə keçid baş vermir 2. URL dəyişmir (https://birmarket.az/ qalır) 3. Səhifə xəta vermir | J37: TS_UI_07 | K37: Davranış saytda təsdiqlənib (GQ cavablanıb); deterministik nəticə, SMS/login tələb etmir → avtomatlaşdırılır. | L37: Pass | M37: Automated | N37: Yes | O37: Gözlənilən nəticə ilə üst-üstə düşür. Gauge avtomat run (Chrome 154, guest): PASS. | P37: 06.10.2026 | Q37: Avtomat (Gauge + Selenium)
A38: TC_SRCH_POS_001 | B38: Mövcud açar sözlə ("iphone") axtarış nəticələri açar sözü ehtiva edən məhsulları qaytarır | C38: Axtarış → Açar söz | D38: P1 - Critical | E38: Pozitiv, Smoke | F38: 1. Brauzer: Google Chrome (son stabil versiya), incognito rejim (cookies/cache təmizdir) 2. İstifadəçi login olmayıb (Guest) 3. Dil: AZ, Şəhər: Bakı (default) 4. Ana səhifə açıqdır: https://birmarket.az/ | G38: 1. Axtarış sahəsinə açar sözü daxil et 2. "Axtar" düyməsinə klik et 3. Nəticə səhifəsindəki məhsul kartlarını yoxla | H38: Açar söz: iphone | I38: 1. Nəticə səhifəsində ən azı 1 məhsul kartı var 2. İlk 10 kartın hər birinin adı "iphone" sözünü ehtiva edir (böyük/kiçik hərfdən asılı olmayaraq) 3. Hər kartda qiymət "₼" valyutası ilə göstərilir | J38: TS_UI_07 | K38: Əsas biznes axını (axtarış = satışın girişi). Yoxlama sabit nəticə sayına yox, invarianta (ad açar sözü ehtiva edir) əsaslanır → flaky deyil, avtomatlaşdırılır. | L38: Pass | M38: Automated | N38: Yes | O38: Gözlənilən nəticə ilə üst-üstə düşür. Gauge avtomat run (Chrome 154, guest): PASS. | P38: 06.10.2026 | Q38: Avtomat (Gauge + Selenium)
A39: TC_SRCH_POS_002 | B39: Axtarış böyük/kiçik hərfə həssas deyil: "IPHONE" və "iphone" eyni nəticəni qaytarır | C39: Axtarış → Case-insensitive | D39: P2 - High | E39: Pozitiv, Edge | F39: 1. Brauzer: Google Chrome (son stabil versiya), incognito rejim (cookies/cache təmizdir) 2. İstifadəçi login olmayıb (Guest) 3. Dil: AZ, Şəhər: Bakı (default) 4. Ana səhifə açıqdır: https://birmarket.az/ | G39: 1. Axtarış sahəsinə 1-ci açar sözü daxil edib axtar 2. İlk 5 məhsulun adlarını qeyd et 3. Ana səhifəyə qayıt 4. Axtarış sahəsinə 2-ci açar sözü daxil edib axtar 5. İlk 5 məhsulun adlarını müqayisə et | H39: Açar söz 1: iphone Açar söz 2: IPHONE | I39: Hər iki axtarışda ilk 5 məhsulun adları və sırası eynidir | J39: TS_UI_07 | K39: İki nəticə bir-biri ilə müqayisə olunur (hardcode yoxdur) → data dəyişsə də stabil; regression-da axtarış alqoritmi dəyişikliyini tutur → avtomatlaşdırılır. | L39: Pass | M39: Automated | N39: Yes | O39: "iphone" və "IPHONE" sorğuları eyni nəticəni qaytardı: "Tapılan məhsul: 300". PASS. | P39: 06.10.2026 | Q39: Avtomat (Gauge + Selenium)
A40: TC_SRCH_POS_006 | B40: Axtarış sahəsinə yazarkən avtomatik təkliflər (autocomplete) göstərilir | C40: Axtarış → Autocomplete | D40: P3 - Medium | E40: Pozitiv, UI | F40: 1. Brauzer: Google Chrome (son stabil versiya), incognito rejim (cookies/cache təmizdir) 2. İstifadəçi login olmayıb (Guest) 3. Dil: AZ, Şəhər: Bakı (default) 4. Ana səhifə açıqdır: https://birmarket.az/ | G40: 1. Axtarış sahəsinə klik et 2. Test datanı yaz, Enter basma 3. Açılan təkliflər siyahısını müşahidə et 4. İlk təklifə klik et | H40: Mətn: sams | I40: 1. Sahənin altında təkliflər siyahısı açılır 2. Təkliflər "sams" hərf birləşməsini ehtiva edir 3. Təklifə klik nəticə səhifəsini açır | J40: TS_UI_07 | K40: Təkliflər populyarlığa görə dinamik dəyişir və debounce/async render olunur; biznes riski aşağı → manual. | L40: Not Run | M40: Manual | N40: No
...

Sheet Automation Strategy
A1: Automation Strategy — Manual vs Avtomat seçimi
A3: 1. Test case-in avtomatlaşdırılması üçün kriteriyalar (hamısı ödənməlidir)
A4: Kod | B4: Kriteriya | C4: İzah
A5: K1 | B5: Regression dəyəri | C5: Hər release-də təkrar icra olunur, P1/P2 biznes funksionallığıdır
A6: K2 | B6: Deterministik nəticə | C6: Assertion invarianta əsaslanır (sıralama, aralıq, cəm, uyğunluq), dəyişən prod data-ya (qiymət, stok, ad) hardcode edilmir
A7: K3 | B7: Xarici asılılıq yoxdur | C7: SMS/OTP, real ödəniş, e-poçt və s. tələb olunmur
A8: K4 | B8: Tələb aydındır | C8: Gözlənilən nəticə dəqiqdir (açıq Grooming Question yoxdur)
A9: K5 | B9: Stabil locator / UI | C9: Element animasiya, A/B test və ya marketinq kontentindən asılı deyil
A10: K6 | B10: Prod-a təhlükəsizdir | C10: Real sifariş, hesab, rəy və ya SMS yaratmır
A12: 2. Manual saxlanılma səbəbləri
A13: Səbəb | B13: Nümunə TC-lər | C13: İzah
A14: SMS OTP | B14: Başlığı [Login] ilə başlayan bütün TC-lər, TC_AUTH_POS_008…024, TC_REG_*, TC_PRF_*, TC_ORD_* | C14: Prod-da OTP bypass yoxdur; real SMS limitlidir. Biznes kritik olanlar "Yes (Manual)" ilə manual regression-dadır (GQ_UI_12)
A15: Qeyri-müəyyən tələb | B15: TC_SRCH_NEG_004, TC_PLP_NEG_004, TC_PLP_BVA_005/012, TC_FAV_NEG_001/003, TC_AUTH_NEG_007, TC_AUTH_EDGE_015 | C15: Gözlənilən nəticə təsdiqlənənə qədər avtomatlaşdırma yanlış assertion yaradar
A16: Vizual / UX | B16: TC_HOME_UI_003/007, TC_PDP_UI_003, TC_CAT_UI_007, TC_XBR_UI_001 | C16: İnsan qiymətləndirməsi tələb edir; marketinq kontenti dəyişkəndir
A17: Dinamik prod data | B17: TC_CART_BVA_005, TC_CHK_BVA_003/004, TC_PDP_POS_006/007, TC_ORD_POS_003 | C17: Stok və qiymətlər real vaxtda dəyişir → flaky risk
A18: Bir dəfəlik / aşağı risk | B18: TC_SRCH_EDGE_005, TC_SRCH_EDGE_007, TC_FTR_POS_001, TC_HOME_POS_002 | C18: Regression ROI aşağıdır
A19: Arxitektura məhdudiyyəti | B19: TC_XBR_UI_002 | C19: Verilmiş arxitektura tək brauzer üçündür, dəyişdirilə bilməz
A21: 3. Anti-flaky qaydalar (avtomatlaşdırılmış testlər üçün)
A22: Qayda | B22: Tətbiq | C22: Niyə
A23: Hardcode data yoxdur | B23: Qiymət və adlar UI-dan oxunub bir-biri ilə müqayisə olunur (kart↔PDP↔səbət) | C23: Prod data dəyişir, test yox
A24: Explicit wait | B24: Thread.sleep əvəzinə element/şərt gözləmələri (visibility, clickable, URL contains) | C24: Şəbəkə gecikməsi testi sındırmır
A25: Müstəqil testlər | B25: Hər test yeni brauzer sessiyası ilə, təmiz cookies, öz preconditions-ı ilə başlayır; test sırası önəmli deyil | C25: Bir testin FAIL-i digərini bloklamır
A26: Stabil test data | B26: Açar sözlər həmişə nəticə qaytaran ("iphone") və heç vaxt qaytarmayan ("qwxzqwxz123") seçilib; məhsul "stokda olan ilk kart" qaydası ilə seçilir | C26: Məhsul satışdan çıxsa da test işləyir
A27: Tolerans | B27: Faiz yuvarlaqlaşdırması ±1%, məbləğ cəmi 0.01 ₼ dəqiqliklə | C27: Yuvarlaqlaşdırma fərqi false FAIL yaratmır
A28: Retry ilə gizlətmə yoxdur | B28: FAIL olan test retry ilə "yaşıl" edilmir, səbəbi araşdırılır | C28: Flaky test real bug-ı gizlədir
A29: Stabillik sübutu | B29: Regression suite ardıcıl 3 dəfə run edilir, hamısı eyni nəticə verməlidir | C29: Exit kriteriyası
A31: 4. Avtomatlaşdırma nəticəsi (icra: 06.10.2026)
A32: Mövzu | B32: Dəyər | C32: Qeyd
A33: Framework | B33: Gauge 1.6 + Selenium 4 + Java 25 + Maven | C33: Verilmiş arxitektura: imp (step) → helper (məntiq) → locator JSON
A34: Spec faylları | B34: specs/ui-testing/birmarket/ — 10 spec + birmarket.cpt | C34: Modullara görə bölünüb (home, language, city, search, plp, pdp, cart, favorites, auth, account)
A35: Locator-lar | B35: src/test/resources/locator/birmarket-*.json — 7 fayl | C35: XPATH və ID; data-info atributlarına üstünlük verilib
A36: Əlavə kod | B36: BirmarketHelper.java + BirmarketImp.java | C36: Qiymət sıralaması, qiymət aralığı, rəqəm müqayisəsi, təkrar cəhdli klik
A37: Smoke run | B37: mvn test "-Dgauge.specs.dir=specs/ui-testing/birmarket" "-Dtags=smoke" | C37: 15/15 PASS (13 ssenari + data-driven account) — popup idarəsi əlavə olunduqdan sonra təkrar təsdiqləndi
A38: Full regression run | B38: mvn test "-Dgauge.specs.dir=specs/ui-testing/birmarket" | C38: 43/43 PASS — ardıcıl 3 run (06.10 23:58, 07.10 00:21, 07.10 12:44), ~11–12 dəq; prod data dəyişsə də (axtarış sayı 300→305, kateqoriyanın 1-ci məhsulu dəyişdi) stabil
A39: Manual-a keçirilən TC-lər | B39: 30 TC | C39: 22 TC stabil locator/prod data səbəbilə, 8 TC (səbətə əlavə) flaky olduğu üçün. Səbəb Test Cases → K sütununda
A41: 5. API avtomatlaşdırması (api.anarabbas.com)
A42: Mövzu | B42: Dəyər | C42: Qeyd
A43: Kriteriya | B43: P1/P2 + deterministik nəticə → avtomat regression; P3/P4 → manual (CallMan) | C43: 123 avtomat, 45 manual TC
A44: Spec faylları | B44: specs/api-testing/final-project/ — 11 spec + fp.cpt | C44: Hər task ayrıca spec; TC ID-ləri ssenari adındadır (traceability)
A45: Əlavə kod | B45: FinalProjectApiHelper.java + FinalProjectApiImp.java | C45: Boş body, kart expiry (Bakı vaxtı +3 il), alıcı body-si
...

Sheet RTM
A1: Scenario ID | B1: Ssenari | C1: İstifadəçi növü | D1: Test Case ID-lər | E1: Cəmi TC | F1: Automated | G1: Manual | H1: Regression | I1: Passed | J1: Coverage Status
A2: TS_UI_01 | B2: Ana səhifə və header | C2: Guest | D2: TC_HOME_POS_001, TC_HOME_POS_002, TC_HOME_POS_006, TC_HOME_POS_009, TC_HOME_POS_010, TC_HOME_POS_011, TC_HOME_POS_012, TC_HOME_POS_013, TC_HOME_POS_014, TC_HOME_POS_015, TC_HOME_POS_016, TC_HOME_POS_017, TC_HOME_POS_018, TC_HOME_POS_019, TC_HOME_UI_003, TC_HOME_UI_007 | E2: =COUNTIF('Test Cases'!$J$2:$J$500,A2) -> 16 | F2: =COUNTIFS('Test Cases'!$J$2:$J$500,A2,'Test Cases'!$M$2:$M$500,"Automated") -> 2 | G2: =COUNTIFS('Test Cases'!$J$2:$J$500,A2,'Test Cases'!$M$2:$M$500,"Manual") -> 14 | H2: =COUNTIFS('Test Cases'!$J$2:$J$500,A2,'Test Cases'!$N$2:$N$500,"Yes*") -> 4 | I2: =COUNTIFS('Test Cases'!$J$2:$J$500,A2,'Test Cases'!$L$2:$L$500,"Pass") -> 5 | J2: =IF(E2=0,"Not Covered",IF(I2=E2,"Covered & Passed","Covered")) -> Covered
A3: TS_UI_02 | B3: Ana səhifə və header | C3: Login | D3: TC_HOME_POS_004, TC_HOME_POS_005 | E3: =COUNTIF('Test Cases'!$J$2:$J$500,A3) -> 2 | F3: =COUNTIFS('Test Cases'!$J$2:$J$500,A3,'Test Cases'!$M$2:$M$500,"Automated") -> 0 | G3: =COUNTIFS('Test Cases'!$J$2:$J$500,A3,'Test Cases'!$M$2:$M$500,"Manual") -> 2 | H3: =COUNTIFS('Test Cases'!$J$2:$J$500,A3,'Test Cases'!$N$2:$N$500,"Yes*") -> 2 | I3: =COUNTIFS('Test Cases'!$J$2:$J$500,A3,'Test Cases'!$L$2:$L$500,"Pass") -> 1 | J3: =IF(E3=0,"Not Covered",IF(I3=E3,"Covered & Passed","Covered")) -> Covered
A4: TS_UI_03 | B4: Dil seçimi (AZ / RU) | C4: Guest | D4: TC_LANG_POS_001, TC_LANG_POS_002, TC_LANG_POS_003, TC_LANG_POS_004 | E4: =COUNTIF('Test Cases'!$J$2:$J$500,A4) -> 4 | F4: =COUNTIFS('Test Cases'!$J$2:$J$500,A4,'Test Cases'!$M$2:$M$500,"Automated") -> 3 | G4: =COUNTIFS('Test Cases'!$J$2:$J$500,A4,'Test Cases'!$M$2:$M$500,"Manual") -> 1 | H4: =COUNTIFS('Test Cases'!$J$2:$J$500,A4,'Test Cases'!$N$2:$N$500,"Yes*") -> 4 | I4: =COUNTIFS('Test Cases'!$J$2:$J$500,A4,'Test Cases'!$L$2:$L$500,"Pass") -> 3 | J4: =IF(E4=0,"Not Covered",IF(I4=E4,"Covered & Passed","Covered")) -> Covered
A5: TS_UI_04 | B5: Dil seçimi (AZ / RU) | C5: Login | D5: TC_LANG_POS_005, TC_LANG_POS_006 | E5: =COUNTIF('Test Cases'!$J$2:$J$500,A5) -> 2 | F5: =COUNTIFS('Test Cases'!$J$2:$J$500,A5,'Test Cases'!$M$2:$M$500,"Automated") -> 0 | G5: =COUNTIFS('Test Cases'!$J$2:$J$500,A5,'Test Cases'!$M$2:$M$500,"Manual") -> 2 | H5: =COUNTIFS('Test Cases'!$J$2:$J$500,A5,'Test Cases'!$N$2:$N$500,"Yes*") -> 1 | I5: =COUNTIFS('Test Cases'!$J$2:$J$500,A5,'Test Cases'!$L$2:$L$500,"Pass") -> 0 | J5: =IF(E5=0,"Not Covered",IF(I5=E5,"Covered & Passed","Covered")) -> Covered
A6: TS_UI_05 | B6: Şəhər seçimi | C6: Guest | D6: TC_CITY_NEG_007, TC_CITY_POS_001, TC_CITY_POS_002, TC_CITY_POS_003 | E6: =COUNTIF('Test Cases'!$J$2:$J$500,A6) -> 4 | F6: =COUNTIFS('Test Cases'!$J$2:$J$500,A6,'Test Cases'!$M$2:$M$500,"Automated") -> 3 | G6: =COUNTIFS('Test Cases'!$J$2:$J$500,A6,'Test Cases'!$M$2:$M$500,"Manual") -> 1 | H6: =COUNTIFS('Test Cases'!$J$2:$J$500,A6,'Test Cases'!$N$2:$N$500,"Yes*") -> 3 | I6: =COUNTIFS('Test Cases'!$J$2:$J$500,A6,'Test Cases'!$L$2:$L$500,"Pass") -> 3 | J6: =IF(E6=0,"Not Covered",IF(I6=E6,"Covered & Passed","Covered")) -> Covered
A7: TS_UI_06 | B7: Şəhər seçimi | C7: Login | D7: TC_CITY_POS_004, TC_CITY_POS_005, TC_CITY_POS_006 | E7: =COUNTIF('Test Cases'!$J$2:$J$500,A7) -> 3 | F7: =COUNTIFS('Test Cases'!$J$2:$J$500,A7,'Test Cases'!$M$2:$M$500,"Automated") -> 0 | G7: =COUNTIFS('Test Cases'!$J$2:$J$500,A7,'Test Cases'!$M$2:$M$500,"Manual") -> 3 | H7: =COUNTIFS('Test Cases'!$J$2:$J$500,A7,'Test Cases'!$N$2:$N$500,"Yes*") -> 0 | I7: =COUNTIFS('Test Cases'!$J$2:$J$500,A7,'Test Cases'!$L$2:$L$500,"Pass") -> 0 | J7: =IF(E7=0,"Not Covered",IF(I7=E7,"Covered & Passed","Covered")) -> Covered
A8: TS_UI_07 | B8: Məhsul axtarışı | C8: Guest | D8: TC_SRCH_EDGE_005, TC_SRCH_EDGE_007, TC_SRCH_EDGE_012, TC_SRCH_NEG_003, TC_SRCH_NEG_004, TC_SRCH_POS_001, TC_SRCH_POS_002, TC_SRCH_POS_006, TC_SRCH_POS_008, TC_SRCH_POS_009, TC_SRCH_POS_010, TC_SRCH_POS_011 | E8: =COUNTIF('Test Cases'!$J$2:$J$500,A8) -> 12 | F8: =COUNTIFS('Test Cases'!$J$2:$J$500,A8,'Test Cases'!$M$2:$M$500,"Automated") -> 6 | G8: =COUNTIFS('Test Cases'!$J$2:$J$500,A8,'Test Cases'!$M$2:$M$500,"Manual") -> 6 | H8: =COUNTIFS('Test Cases'!$J$2:$J$500,A8,'Test Cases'!$N$2:$N$500,"Yes*") -> 7 | I8: =COUNTIFS('Test Cases'!$J$2:$J$500,A8,'Test Cases'!$L$2:$L$500,"Pass") -> 7 | J8: =IF(E8=0,"Not Covered",IF(I8=E8,"Covered & Passed","Covered")) -> Covered
A9: TS_UI_08 | B9: Məhsul axtarışı | C9: Login | D9: TC_SRCH_POS_013 | E9: =COUNTIF('Test Cases'!$J$2:$J$500,A9) -> 1 | F9: =COUNTIFS('Test Cases'!$J$2:$J$500,A9,'Test Cases'!$M$2:$M$500,"Automated") -> 0 | G9: =COUNTIFS('Test Cases'!$J$2:$J$500,A9,'Test Cases'!$M$2:$M$500,"Manual") -> 1 | H9: =COUNTIFS('Test Cases'!$J$2:$J$500,A9,'Test Cases'!$N$2:$N$500,"Yes*") -> 0 | I9: =COUNTIFS('Test Cases'!$J$2:$J$500,A9,'Test Cases'!$L$2:$L$500,"Pass") -> 0 | J9: =IF(E9=0,"Not Covered",IF(I9=E9,"Covered & Passed","Covered")) -> Covered
A10: TS_UI_09 | B10: Kataloq və kateqoriya naviqasiyası | C10: Guest | D10: TC_CAT_NEG_006, TC_CAT_POS_001, TC_CAT_POS_002, TC_CAT_POS_003, TC_CAT_POS_004, TC_CAT_POS_005, TC_CAT_UI_007 | E10: =COUNTIF('Test Cases'!$J$2:$J$500,A10) -> 7 | F10: =COUNTIFS('Test Cases'!$J$2:$J$500,A10,'Test Cases'!$M$2:$M$500,"Automated") -> 3 | G10: =COUNTIFS('Test Cases'!$J$2:$J$500,A10,'Test Cases'!$M$2:$M$500,"Manual") -> 4 | H10: =COUNTIFS('Test Cases'!$J$2:$J$500,A10,'Test Cases'!$N$2:$N$500,"Yes*") -> 5 | I10: =COUNTIFS('Test Cases'!$J$2:$J$500,A10,'Test Cases'!$L$2:$L$500,"Pass") -> 4 | J10: =IF(E10=0,"Not Covered",IF(I10=E10,"Covered & Passed","Covered")) -> Covered
A11: TS_UI_10 | B11: Məhsul siyahısı: sıralama, filtr, səhifələmə | C11: Guest | D11: TC_PLP_BVA_005, TC_PLP_BVA_012, TC_PLP_NEG_004, TC_PLP_NEG_013, TC_PLP_NEG_014, TC_PLP_POS_001, TC_PLP_POS_002, TC_PLP_POS_003, TC_PLP_POS_006, TC_PLP_POS_007, TC_PLP_POS_008, TC_PLP_POS_009, TC_PLP_POS_010, TC_PLP_POS_011, TC_PLP_POS_015, TC_PLP_POS_016, TC_PLP_POS_017, TC_PLP_POS_018, TC_PLP_POS_019, TC_PLP_POS_020, TC_PLP_POS_022, TC_PLP_POS_023, TC_PLP_POS_024, TC_PLP_POS_025, TC_PLP_POS_026, TC_PLP_POS_027, TC_PLP_POS_028, TC_PLP_POS_029, TC_PLP_UI_021 | E11: =COUNTIF('Test Cases'!$J$2:$J$500,A11) -> 29 | F11: =COUNTIFS('Test Cases'!$J$2:$J$500,A11,'Test Cases'!$M$2:$M$500,"Automated") -> 11 | G11: =COUNTIFS('Test Cases'!$J$2:$J$500,A11,'Test Cases'!$M$2:$M$500,"Manual") -> 18 | H11: =COUNTIFS('Test Cases'!$J$2:$J$500,A11,'Test Cases'!$N$2:$N$500,"Yes*") -> 18 | I11: =COUNTIFS('Test Cases'!$J$2:$J$500,A11,'Test Cases'!$L$2:$L$500,"Pass") -> 13 | J11: =IF(E11=0,"Not Covered",IF(I11=E11,"Covered & Passed","Covered")) -> Covered
A12: TS_UI_11 | B12: Məhsul detal səhifəsi (PDP) | C12: Guest | D12: TC_PDP_NEG_005, TC_PDP_NEG_012, TC_PDP_POS_001, TC_PDP_POS_002, TC_PDP_POS_004, TC_PDP_POS_006, TC_PDP_POS_007, TC_PDP_POS_008, TC_PDP_POS_009, TC_PDP_POS_010, TC_PDP_POS_011, TC_PDP_POS_015, TC_PDP_POS_016, TC_PDP_UI_003 | E12: =COUNTIF('Test Cases'!$J$2:$J$500,A12) -> 14 | F12: =COUNTIFS('Test Cases'!$J$2:$J$500,A12,'Test Cases'!$M$2:$M$500,"Automated") -> 4 | G12: =COUNTIFS('Test Cases'!$J$2:$J$500,A12,'Test Cases'!$M$2:$M$500,"Manual") -> 10 | H12: =COUNTIFS('Test Cases'!$J$2:$J$500,A12,'Test Cases'!$N$2:$N$500,"Yes*") -> 6 | I12: =COUNTIFS('Test Cases'!$J$2:$J$500,A12,'Test Cases'!$L$2:$L$500,"Pass") -> 5 | J12: =IF(E12=0,"Not Covered",IF(I12=E12,"Covered & Passed","Covered")) -> Covered
A13: TS_UI_12 | B13: Məhsul detal səhifəsi (PDP) | C13: Login | D13: TC_PDP_NEG_014, TC_PDP_POS_013 | E13: =COUNTIF('Test Cases'!$J$2:$J$500,A13) -> 2 | F13: =COUNTIFS('Test Cases'!$J$2:$J$500,A13,'Test Cases'!$M$2:$M$500,"Automated") -> 0 | G13: =COUNTIFS('Test Cases'!$J$2:$J$500,A13,'Test Cases'!$M$2:$M$500,"Manual") -> 2 | H13: =COUNTIFS('Test Cases'!$J$2:$J$500,A13,'Test Cases'!$N$2:$N$500,"Yes*") -> 1 | I13: =COUNTIFS('Test Cases'!$J$2:$J$500,A13,'Test Cases'!$L$2:$L$500,"Pass") -> 1 | J13: =IF(E13=0,"Not Covered",IF(I13=E13,"Covered & Passed","Covered")) -> Covered
... A30: TS_UI_29 | B30: Bir Bonus: ID kart və əməliyyat tarixçəsi | C30: Login | D30: TC_BON_POS_001, TC_BON_POS_002, TC_BON_POS_003, TC_BON_POS_005, TC_BON_UI_004, TC_TRX_BVA_007, TC_TRX_NEG_009, TC_TRX_POS_006, TC_TRX_POS_008 | E30: =COUNTIF('Test Cases'!$J$2:$J$500,A30) -> 9 | F30: =COUNTIFS('Test Cases'!$J$2:$J$500,A30,'Test Cases'!$M$2:$M$500,"Automated") -> 0 | G30: =COUNTIFS('Test Cases'!$J$2:$J$500,A30,'Test Cases'!$M$2:$M$500,"Manual") -> 9 | H30: =COUNTIFS('Test Cases'!$J$2:$J$500,A30,'Test Cases'!$N$2:$N$500,"Yes*") -> 1 | I30: =COUNTIFS('Test Cases'!$J$2:$J$500,A30,'Test Cases'!$L$2:$L$500,"Pass") -> 0 | J30: =IF(E30=0,"Not Covered",IF(I30=E30,"Covered & Passed","Covered")) -> Covered

Sheet Summary
A1: Summary — UI Test Göstəriciləri
A3: Göstərici
A4: Cəmi UI test case | B4: =COUNTA('Test Cases'!$A$2:$A$500) -> 228
A5: Cəmi ssenari | B5: =COUNTA('Test Scenarios'!$A$2:$A$100) -> 29
A7: Prioritet üzrə
A8: Göstərici | B8: Say | C8: Faiz
A9: P1 - Critical | B9: =COUNTIF('Test Cases'!$D$2:$D$500,"P1 - Critical") -> 36 | C9: =IFERROR(B9/$B$4,0) -> 0.15789474
A10: P2 - High | B10: =COUNTIF('Test Cases'!$D$2:$D$500,"P2 - High") -> 93 | C10: =IFERROR(B10/$B$4,0) -> 0.40789474
A11: P3 - Medium | B11: =COUNTIF('Test Cases'!$D$2:$D$500,"P3 - Medium") -> 92 | C11: =IFERROR(B11/$B$4,0) -> 0.40350877
A12: P4 - Low | B12: =COUNTIF('Test Cases'!$D$2:$D$500,"P4 - Low") -> 7 | C12: =IFERROR(B12/$B$4,0) -> 0.030701754
A14: Test növü üzrə (bir TC bir neçə növə aid ola bilər)
A15: Göstərici | B15: Say | C15: Faiz
A16: Pozitiv | B16: =COUNTIF('Test Cases'!$E$2:$E$500,"*Pozitiv*") -> 148 | C16: =IFERROR(B16/$B$4,0) -> 0.64912281
A17: Neqativ | B17: =COUNTIF('Test Cases'!$E$2:$E$500,"*Neqativ*") -> 59 | C17: =IFERROR(B17/$B$4,0) -> 0.25877193
A18: BVA | B18: =COUNTIF('Test Cases'!$E$2:$E$500,"*BVA*") -> 24 | C18: =IFERROR(B18/$B$4,0) -> 0.10526316
A19: EP | B19: =COUNTIF('Test Cases'!$E$2:$E$500,"*EP*") -> 17 | C19: =IFERROR(B19/$B$4,0) -> 0.074561404
A20: Edge | B20: =COUNTIF('Test Cases'!$E$2:$E$500,"*Edge*") -> 10 | C20: =IFERROR(B20/$B$4,0) -> 0.043859649
